<mujoco model="xarm_gripper">
  <compiler angle="radian"/>

  <asset>
    <material name="white" rgba="1 1 1 1"/>
    <material name="black" rgba="0.149 0.149 0.149 1"/>
    <mesh name="xarm_gripper_base_link" file="meshes/xarm_gripper/base_link.stl"/>
    <mesh name="xarm_gripper_left_outer_knuckle" file="meshes/xarm_gripper/left_outer_knuckle.stl"/>
    <mesh name="xarm_gripper_left_finger" file="meshes/xarm_gripper/left_finger.stl"/>
    <mesh name="xarm_gripper_left_inner_knuckle" file="meshes/xarm_gripper/left_inner_knuckle.stl"/>
    <mesh name="xarm_gripper_right_outer_knuckle" file="meshes/xarm_gripper/right_outer_knuckle.stl"/>
    <mesh name="xarm_gripper_right_finger" file="meshes/xarm_gripper/right_finger.stl"/>
    <mesh name="xarm_gripper_right_inner_knuckle" file="meshes/xarm_gripper/right_inner_knuckle.stl"/>
  </asset>

  <actuator>
    <position name="left_drive" joint="left_driver_joint" ctrlrange="0 0.85" kp="1000" forcelimited="true" forcerange="-50 50"/>
    <position name="right_drive" joint="right_driver_joint" ctrlrange="0 0.85" kp="1000" forcelimited="true" forcerange="-50 50"/>
  </actuator>

  <worldbody>
    <body name="xarm_gripper_base_link" pos="0 0 0">
      <site name="ft_frame" pos="0 0 0" size="0.01 0.01 0.01" rgba="1 0 0 1" type="sphere" group="1"/>
      <inertial pos="-0.00065489 -0.0018497 0.048028" mass="0.54156" diaginertia="0.000471093 0.000332307 0.000254799"/>
      <geom type="mesh" mesh="xarm_gripper_base_link" material="white" contype="0" conaffinity="0" group="1" name="base_visual"/>
      <geom type="mesh" mesh="xarm_gripper_base_link" rgba="0.7 0.7 0.7 1" contype="1" conaffinity="1" group="0" name="base_collision"/>
      
      <!-- Left Outer Knuckle -->
      <body name="left_outer_knuckle" pos="0 0.035 0.059098">
        <inertial pos="0 0.021559 0.015181" mass="0.033618" diaginertia="1.9111e-05 1.79089e-05 1.90167e-06"/>
        <joint name="left_driver_joint" type="hinge" axis="1 0 0" range="0 0.85" damping="5" armature="1.0" frictionloss="1.0"/>
        <geom type="mesh" mesh="xarm_gripper_left_outer_knuckle" material="black" contype="0" conaffinity="0" group="1" name="left_outer_knuckle_visual"/>
        <geom type="mesh" mesh="xarm_gripper_left_outer_knuckle" rgba="0.7 0.7 0.7 1" contype="1" conaffinity="1" group="0" name="left_outer_knuckle_collision"/>
        <!-- Left Finger -->
        <body name="left_finger" pos="0 0.035465 0.042039">
          <inertial pos="0 -0.016413 0.029258" mass="0.048304" diaginertia="1.88037e-05 1.7493e-05 3.56792e-06"/>
          <joint name="left_finger_joint" type="hinge" axis="-1 0 0" range="0 0.85" damping="2" armature="1.0" frictionloss="1.0"/>
          <geom type="mesh" mesh="xarm_gripper_left_finger" material="black" contype="0" conaffinity="0" group="1" name="left_finger_visual"/>
          <geom type="mesh" mesh="xarm_gripper_left_finger" rgba="0.7 0.7 0.7 1" contype="1" conaffinity="1" group="0" name="left_finger_collision"/>
          <geom type="box" pos="0 -0.024003 0.032" size="0.015 0.002 0.0095" rgba="0.0 0.1 0.7 1" contype="1" conaffinity="1" group="0" friction="0.7 0.005 0.0001" name="left_finger_pad"/>
        </body>
      </body>

      <!-- Left Inner Knuckle -->
      <body name="left_inner_knuckle" pos="0 0.02 0.074098">
        <inertial pos="1.86601e-06 0.0220468 0.0261335" mass="0.0230126" diaginertia="8.34216e-06 6.0949e-06 2.75601e-06"/>
        <joint name="left_inner_knuckle_joint" type="hinge" axis="1 0 0" range="0 0.85" damping="2" armature="1.0" frictionloss="1.0"/>
        <geom type="mesh" mesh="xarm_gripper_left_inner_knuckle" material="black" contype="0" conaffinity="0" group="1" name="left_inner_knuckle_visual"/>
        <geom type="mesh" mesh="xarm_gripper_left_inner_knuckle" rgba="0.7 0.7 0.7 1" contype="1" conaffinity="1" group="0" name="left_inner_knuckle_collision"/>
      </body>

      <!-- Right Outer Knuckle -->
      <body name="right_outer_knuckle" pos="0 -0.035 0.059098">
        <inertial pos="0 -0.021559 0.015181" mass="0.033618" diaginertia="1.9111e-05 1.79089e-05 1.90167e-06"/>
        <joint name="right_driver_joint" type="hinge" axis="-1 0 0" range="0 0.85" damping="5" armature="1.0" frictionloss="1.0"/>
        <geom type="mesh" mesh="xarm_gripper_right_outer_knuckle" material="black" contype="0" conaffinity="0" group="1" name="right_outer_knuckle_visual"/>
        <geom type="mesh" mesh="xarm_gripper_right_outer_knuckle" rgba="0.7 0.7 0.7 1" contype="1" conaffinity="1" group="0" name="right_outer_knuckle_collision"/>
        <!-- Right Finger -->
        <body name="right_finger" pos="0 -0.035465 0.042039">
          <inertial pos="0 0.016413 0.029258" mass="0.048304" diaginertia="1.88038e-05 1.7493e-05 3.56779e-06"/>
          <joint name="right_finger_joint" type="hinge" axis="1 0 0" range="0 0.85" damping="2" armature="1.0" frictionloss="1.0"/>
          <geom type="mesh" mesh="xarm_gripper_right_finger" material="black" contype="0" conaffinity="0" group="1" name="right_finger_visual"/>
          <geom type="mesh" mesh="xarm_gripper_right_finger" rgba="0.7 0.7 0.7 1" contype="1" conaffinity="1" group="0" name="right_finger_collision"/>
          <geom type="box" pos="0 0.024003 0.032" size="0.015 0.002 0.0095" rgba="0.0 0.1 0.7 1" contype="1" conaffinity="1" group="0" friction="0.7 0.005 0.0001" name="right_finger_pad"/>
        </body>
      </body>

      <!-- Right Inner Knuckle -->
      <body name="right_inner_knuckle" pos="0 -0.02 0.074098">
        <inertial pos="1.866e-06 -0.022047 0.026133" mass="0.023013" diaginertia="8.34209e-06 6.0949e-06 2.75601e-06"/>
        <joint name="right_inner_knuckle_joint" type="hinge" axis="-1 0 0" range="0 0.85" damping="2" armature="1.0" frictionloss="1.0"/>
        <geom type="mesh" mesh="xarm_gripper_right_inner_knuckle" material="black" contype="0" conaffinity="0" group="1" name="right_inner_knuckle_visual"/>
        <geom type="mesh" mesh="xarm_gripper_right_inner_knuckle" rgba="0.7 0.7 0.7 1" contype="1" conaffinity="1" group="0" name="right_inner_knuckle_collision"/>
      </body>

      <!-- End-Effector Site -->
      <body name="eef" pos="0 0 0.2" quat="1 0 0 0">
        <site name="grip_site" pos="0 0 0" size="0.01 0.01 0.01" rgba="1 0 0 0.5" type="sphere" group="1"/>
        <site name="ee_x" pos="0.1 0 0" size="0.005 0.1" quat="0.707105 0 0.707108 0" rgba="1 0 0 0" type="cylinder" group="1"/>
        <site name="ee_y" pos="0 0.1 0" size="0.005 0.1" quat="0.707105 0.707108 0 0" rgba="0 1 0 0" type="cylinder" group="1"/>
        <site name="ee_z" pos="0 0 0.1" size="0.005 0.1" quat="1 0 0 0" rgba="0 0 1 0" type="cylinder" group="1"/>
        <site name="grip_site_cylinder" pos="0 0 0" size="0.005 10" rgba="0 1 0 0.3" type="cylinder" group="1"/>
      </body>
    </body>
  </worldbody>

  <equality>
    <joint joint1="left_driver_joint" joint2="left_finger_joint" polycoef="0 1 0 0 0"/>
    <joint joint1="left_driver_joint" joint2="left_inner_knuckle_joint" polycoef="0 1 0 0 0"/>
    <joint joint1="right_driver_joint" joint2="right_finger_joint" polycoef="0 1 0 0 0"/>
    <joint joint1="right_driver_joint" joint2="right_inner_knuckle_joint" polycoef="0 1 0 0 0"/>
  </equality>
  
  <sensor>
    <force name="force_ee" site="ft_frame"/>
    <torque name="torque_ee" site="ft_frame"/>
  </sensor>
</mujoco>
